Workbook

Sheet База продуктов
B2: БАЗА ПРОДУКТОВ ЭМПИЛС — СПРАВОЧНИК ДЛЯ TCO-КАЛЬКУЛЯТОРА
B3: Выбирайте продукты на листе «Калькулятор» — данные подставляются автоматически
B5: Категория | C5: Продукт | D5: Бренд | E5: Цена (₽/кг) | F5: Расход (кг/м²) | G5: Назначение | H5: Код
B6: Грунтовка | C6: ОРЕОЛ Грунт универсальный | D6: ОРЕОЛ | E6: 130 | F6: 0.15 | G6: Грунтование под шпатлёвку и краску | H6: Г001
B7: Грунтовка | C7: NEWTONE Грунт глубокого проникновения | D7: NEWTONE | E7: 180 | F7: 0.12 | G7: Укрепление рыхлых оснований | H7: Г002
B8: Грунтовка | C8: AVANTGARDE Грунт премиум | D8: AVANTGARDE | E8: 350 | F8: 0.1 | G8: Под премиум-систему | H8: Г003
B9: Грунтовка | C9: ОРЕОЛ Бетоноконтакт | D9: ОРЕОЛ | E9: 220 | F9: 0.2 | G9: Гладкие невпитывающие основания | H9: Г004
B10: Грунтовка | C10: NEWTONE Грунт антиплесневый | D10: NEWTONE | E10: 280 | F10: 0.12 | G10: Влажные зоны | H10: Г005
B11: Шпатлёвка стартовая | C11: ОРЕОЛ Шпатлёвка стартовая | D11: ОРЕОЛ | E11: 120 | F11: 1.2 | G11: Выравнивание, слой до 10 мм | H11: С001
B12: Шпатлёвка стартовая | C12: NEWTONE Шпатлёвка базовая | D12: NEWTONE | E12: 170 | F12: 1 | G12: Базовое выравнивание, до 8 мм | H12: С002
B13: Шпатлёвка стартовая | C13: AVANTGARDE Шпатлёвка сверхпрочная | D13: AVANTGARDE | E13: 280 | F13: 0.8 | G13: С армирующим эффектом | H13: С003
B14: Шпатлёвка финишная | C14: NEWTONE Шпатлёвка финишная | D14: NEWTONE | E14: 250 | F14: 0.6 | G14: Финиш, слой до 3 мм | H14: Ф001
B15: Шпатлёвка финишная | C15: AVANTGARDE Суперфинишная | D15: AVANTGARDE | E15: 420 | F15: 0.5 | G15: Идеально гладкая поверхность | H15: Ф002
B16: Шпатлёвка финишная | C16: ОРЕОЛ Шпатлёвка финишная | D16: ОРЕОЛ | E16: 160 | F16: 0.7 | G16: Эконом финиш, до 2 мм | H16: Ф003
B17: Краска ВД | C17: ОРЕОЛ Краска ВД интерьерная | D17: ОРЕОЛ | E17: 180 | F17: 0.18 | G17: Базовая ВД для сухих помещений | H17: К001
... B32: Эмаль | C32: Расцвет Эмаль для полов | D32: Расцвет | E32: 280 | F32: 0.12 | G32: Износостойкая для полов | H32: Э003

Sheet Калькулятор TCO
B2: TCO-КАЛЬКУЛЯТОР ЭМПИЛС v2.0
B3: Выбирайте продукты из справочника — расход и цена подставляются автоматически!
B5: ВВОД ДАННЫХ
B6: Тип помещения | C6: комната 20 м² | D6: Выберите из списка
B7: Площадь поверхности (м²) | C7: 42 | D7: Окрашиваемая площадь
B8: Высота потолков (м) | C8: 2.7 | D8: Стандарт 2.5–2.7
B9: Количество слоёв краски | C9: 2 | D9: Обычно 2 слоя
B10: Стоимость работы — грунтовка (₽/м²) | C10: 80 | D10: Средняя по региону
B11: Стоимость работы — шпатлёвка (₽/м²) | C11: 120 | D11: Зависит от сложности
B12: Стоимость работы — покраска (₽/м²) | C12: 150 | D12: Включая валик/кисть
B14: ВЫБОР ПРОДУКТОВ ИЗ СПРАВОЧНИКА (жёлтые ячейки — выберите продукт)
B15: Этап работ | C15: Продукт (код) | D15: Расход (кг/м²) | E15: Цена (₽/кг) | F15: Слои
B16: СИСТЕМА «ЭКОНОМ» (ОРЕОЛ)
B17: Грунтовка | C17: Г001 | D17: =ИНДЕКС('База продуктов'!F6:F31;ПОИСКПОЗ(C17;'База продуктов'!H6:H31;0)) | E17: =ИНДЕКС('База продуктов'!E6:E31;ПОИСКПОЗ(C17;'База продуктов'!H6:H31;0)) | F17: 1
B18: Шпатлёвка стартовая | C18: С001 | D18: =ИНДЕКС('База продуктов'!F6:F31;ПОИСКПОЗ(C18;'База продуктов'!H6:H31;0)) | E18: =ИНДЕКС('База продуктов'!E6:E31;ПОИСКПОЗ(C18;'База продуктов'!H6:H31;0)) | F18: 1
B19: Шпатлёвка финишная | C19: Ф003 | D19: =ИНДЕКС('База продуктов'!F6:F31;ПОИСКПОЗ(C19;'База продуктов'!H6:H31;0)) | E19: =ИНДЕКС('База продуктов'!E6:E31;ПОИСКПОЗ(C19;'База продуктов'!H6:H31;0)) | F19: 1
B20: Краска ВД | C20: К001 | D20: =ИНДЕКС('База продуктов'!F6:F31;ПОИСКПОЗ(C20;'База продуктов'!H6:H31;0)) | E20: =ИНДЕКС('База продуктов'!E6:E31;ПОИСКПОЗ(C20;'База продуктов'!H6:H31;0)) | F20: =C9
B22: СИСТЕМА «ПРЕМИУМ» (AVANTGARDE + NEWTONE)
B23: Грунтовка | C23: Г003 | D23: =ИНДЕКС('База продуктов'!F6:F31;ПОИСКПОЗ(C23;'База продуктов'!H6:H31;0)) | E23: =ИНДЕКС('База продуктов'!E6:E31;ПОИСКПОЗ(C23;'База продуктов'!H6:H31;0)) | F23: 1
B24: Шпатлёвка стартовая | C24: С002 | D24: =ИНДЕКС('База продуктов'!F6:F31;ПОИСКПОЗ(C24;'База продуктов'!H6:H31;0)) | E24: =ИНДЕКС('База продуктов'!E6:E31;ПОИСКПОЗ(C24;'База продуктов'!H6:H31;0)) | F24: 1
B25: Шпатлёвка финишная | C25: Ф002 | D25: =ИНДЕКС('База продуктов'!F6:F31;ПОИСКПОЗ(C25;'База продуктов'!H6:H31;0)) | E25: =ИНДЕКС('База продуктов'!E6:E31;ПОИСКПОЗ(C25;'База продуктов'!H6:H31;0)) | F25: 1
B26: Краска ВД | C26: К003 | D26: =ИНДЕКС('База продуктов'!F6:F31;ПОИСКПОЗ(C26;'База продуктов'!H6:H31;0)) | E26: =ИНДЕКС('База продуктов'!E6:E31;ПОИСКПОЗ(C26;'База продуктов'!H6:H31;0)) | F26: =C9
B27: Лак защитный | C27: Л002 | D27: =ИНДЕКС('База продуктов'!F6:F31;ПОИСКПОЗ(C27;'База продуктов'!H6:H31;0)) | E27: =ИНДЕКС('База продуктов'!E6:E31;ПОИСКПОЗ(C27;'База продуктов'!H6:H31;0)) | F27: 1
B29: РАСЧЁТ СТОИМОСТИ МАТЕРИАЛОВ
B30: Материал | C30: Расход на площадь (кг) | D30: Цена (₽/кг) | E30: Стоимость (₽)
B31: СИСТЕМА «ЭКОНОМ»
B32: Грунтовка | C32: =D17*C7 | D32: =E17 | E32: =C32*D32*F17
B33: Шпатлёвка стартовая | C33: =D18*C7 | D33: =E18 | E33: =C33*D33*F18
B34: Шпатлёвка финишная | C34: =D19*C7 | D34: =E19 | E34: =C34*D34*F19
B35: Краска ВД | C35: =D20*C7 | D35: =E20 | E35: =C35*D35*F20
B36: ИТОГО материалы (Эконом) | E36: =SUM(E32:E35)
B38: СИСТЕМА «ПРЕМИУМ»
B39: Грунтовка | C39: =D23*C7 | D39: =E23 | E39: =C39*D39*F23
B40: Шпатлёвка стартовая | C40: =D24*C7 | D40: =E24 | E40: =C40*D40*F24
B41: Шпатлёвка финишная | C41: =D25*C7 | D41: =E25 | E41: =C41*D41*F25
B42: Краска ВД | C42: =D26*C7 | D42: =E26 | E42: =C42*D42*F26
B43: Лак защитный | C43: =D27*C7 | D43: =E27 | E43: =C43*D43*F27
B44: ИТОГО материалы (Премиум) | E44: =SUM(E39:E43)
B46: СВОДНЫЙ РАСЧЁТ TCO
B47: Показатель | C47: Эконом | D47: Премиум | E47: Разница
...

Sheet Сценарии
B2: ПРЕДЗАПОЛНЕННЫЕ СЦЕНАРИИ TCO
B4: Сценарий | C4: Площадь (м²) | D4: Высота (м) | E4: Слои | F4: Грунтовка (₽/м²) | G4: Шпатлёвка (₽/м²) | H4: Покраска (₽/м²)
B5: Комната 20 м² | C5: 45 | D5: 2.7 | E5: 2 | F5: 80 | G5: 120 | H5: 150
B6: Ванная 6 м² | C6: 22 | D6: 2.5 | E6: 2 | F6: 100 | G6: 150 | H6: 180
B7: Фасад дома 100 м² | C7: 100 | D7: 3 | E7: 2 | F7: 120 | G7: 0 | H7: 200
B8: Деревянный домик 40 м² | C8: 50 | D8: 2.5 | E8: 2 | F8: 100 | G8: 80 | H8: 180
B9: Детская 15 м² | C9: 35 | D9: 2.7 | E9: 2 | F9: 80 | G9: 120 | H9: 150
B10: Офис 50 м² | C10: 120 | D10: 3 | E10: 2 | F10: 80 | G10: 100 | H10: 140
B11: Лоджия 8 м² | C11: 20 | D11: 2.5 | E11: 2 | F11: 100 | G11: 100 | H11: 160

Sheet Инструкция
B2: ИНСТРУКЦИЯ МЕНЕДЖЕРА — TCO-КАЛЬКУЛЯТОР v2.0
B4: КАК ПОЛЬЗОВАТЬСЯ v2.0
B6: 1. Откройте лист «Калькулятор TCO»
B7: 2. В жёлтые ячейки введите параметры: площадь, высота, стоимость работ
B8: 3. В разделе «Выбор продуктов» кликните на жёлтую ячейку с кодом продукта
B9: 4. Из выпадающего списка выберите нужный продукт — расход и цена подставляются автоматически!
B10: 5. Все расчёты пересчитаются мгновенно
B12: ЧТО НОВОГО В v2.0
B14: • База продуктов — 27 позиций Эмпилс с ценами и расходами
B15: • Выбор продукта из выпадающего списка — не нужно помнить цифры
B16: • Расход и цена подставляются автоматически через формулы ИНДЕКС+ПОИСКПОЗ
B17: • Категории: грунтовки, шпатлёвки (старт/финиш), краски ВД, фасадные, лаки, эмали, декор
... B37: • Жёлтые ячейки — для ввода данных, остальные рассчитываются автоматически
